Workbook

Sheet Sheet1
B2: 46266
B3: start row | C3: 770562
B4: after row | C4: 507385
C5: 263177
B6: del % | C6: 34.153903
D7: avg_len
B8: total trips | C8: 507385 | D8: 0.010300962 | H8: members_classic_bike | I8: 130103
B9: classic bikes | C9: 189268 | D9: 0.012733157 | H9: members_e-bike | I9: 188922
B10: e-bikes | C10: 318117 | D10: 0.0088538948 | H10: casula_clssic_bike | I10: 59165
B11: members | C11: 319025 | D11: 0.0084746762 | H11: casual_e-bike | I11: 129195
B12: casual | C12: 188360 | D12: 0.013394139
C14: total trips | D14: clasic bikes | E14: e-bikes | F14: members | G14: casual | I14: avg_len | J14: avg_len(classic bike) | K14: avg_len (e-bike) | L14: avg_len (member) | M14: avg_len (casual)
B15: Monday | C15: 66314 | D15: 25621 | E15: 40693 | F15: 42649 | G15: 23665 | H15: Monday | I15: 0.010497736 | J15: 0.013215462 | K15: 0.0087866095 | L15: 0.0084926778 | M15: 0.014111246
B16: Tuesday | C16: 88918 | D16: 33187 | E16: 55731 | F16: 63601 | G16: 25317 | H16: Tuesday | I16: 0.0089413578 | J16: 0.010496577 | K16: 0.0080152475 | L16: 0.0081054386 | M16: 0.011041342
B17: Wednesday | C17: 73824 | D17: 26439 | E17: 47385 | F17: 52299 | G17: 21525 | H17: Wednesday | I17: 0.008601195 | J17: 0.010428666 | K17: 0.0075815368 | L17: 0.007839775 | M17: 0.010451207
B18: Thursday | C18: 68815 | D18: 25299 | E18: 43516 | F18: 46640 | G18: 22175 | H18: Thursday | I18: 0.009604753 | J18: 0.012011749 | K18: 0.0082053923 | L18: 0.0082396845 | M18: 0.01247586
B19: Friday | C19: 75917 | D19: 27199 | E19: 48718 | F19: 46278 | G19: 29639 | H19: Friday | I19: 0.010201973 | J19: 0.012530593 | K19: 0.0089019164 | L19: 0.0083939892 | M19: 0.013024938
B20: Saturday | C20: 73575 | D20: 27913 | E20: 45662 | F20: 36891 | G20: 36684 | H20: Saturday | I20: 0.012103519 | J20: 0.014905055 | K20: 0.010390952 | L20: 0.0094887415 | M20: 0.014733052
B21: Sunday | C21: 60022 | D21: 23610 | E21: 36412 | F21: 30667 | G21: 29355 | H21: Sunday | I21: 0.012902165 | J21: 0.01637284 | K21: 0.010651736 | L21: 0.0095574358 | M21: 0.016396384
B24: 46235
B25: start row | C25: 868191
B26: after row | C26: 561330
C27: 306861
B28: del % | C28: 35.344872
D29: avg_len
B30: total trips | C30: 561330 | D30: 0.01087672 | H30: members_classic_bike | I30: 147354
B31: classic bikes | C31: 222889 | D31: 0.013382751 | H31: members_e-bike | I31: 194146
B32: e-bikes | C32: 338441 | D32: 0.0092263091 | H32: casula_clssic_bike | I32: 75535
B33: members | C33: 341500 | D33: 0.0088211037 | H33: casual_e-bike | I33: 144295
B34: casual | C34: 219830 | D34: 0.014070065
C36: total trips | D36: clasic bikes | E36: e-bikes | F36: members | G36: casual | I36: avg_len | J36: avg_len(classic bike) | K36: avg_len (e-bike) | L36: avg_len (member) | M36: avg_len (casual)
B37: Monday | C37: 83240 | D37: 33270 | E37: 49970 | F37: 55784 | G37: 27456 | H37: Monday | I37: 0.01007414 | J37: 0.012243899 | K37: 0.0086295159 | L37: 0.0084001372 | M37: 0.013475312
B38: Tuesday | C38: 73667 | D38: 29954 | E38: 43713 | F38: 50198 | G38: 23469 | H38: Tuesday | I38: 0.0099109822 | J38: 0.011807171 | K38: 0.008611633 | L38: 0.0084795969 | M38: 0.012972582
B39: Wednesday | C39: 73648 | D39: 29314 | E39: 44334 | F39: 50229 | G39: 23419 | H39: Wednesday | I39: 0.0095671033 | J39: 0.011468417 | K39: 0.0083099391 | L39: 0.00838914 | M39: 0.012093595
B40: Thursday | C40: 70892 | D40: 27344 | E40: 43548 | F40: 46922 | G40: 23970 | H40: Thursday | I40: 0.009798491 | J40: 0.011996249 | K40: 0.0084185084 | L40: 0.008432969 | M40: 0.012471542
B41: Friday | C41: 81193 | D41: 30513 | E41: 50680 | F41: 47549 | G41: 33644 | H41: Friday | I41: 0.011032991 | J41: 0.013926113 | K41: 0.0092911244 | L41: 0.0087648318 | M41: 0.014238577
B42: Saturday | C42: 96600 | D42: 38503 | E42: 58097 | F42: 47569 | G42: 49031 | H42: Saturday | I42: 0.012554518 | J42: 0.015717597 | K42: 0.01045823 | L42: 0.0097138138 | M42: 0.015310518
B43: Sunday | C43: 82090 | D43: 33991 | E43: 48099 | F43: 43249 | G43: 38841 | H43: Sunday | I43: 0.01253435 | J43: 0.01551966 | K43: 0.010424667 | L43: 0.0097632215 | M43: 0.01561997
B47: 46204
B48: start row | C48: 869051
...

Sheet yearly
C2: total | D2: avg_len
B3: 45931 | C3: =Sheet1!C252 -> 417877 | D3: =Sheet1!D252 -> 0.010570443
B4: 45962 | C4: =Sheet1!C230 -> 235010 | D4: =Sheet1!D230 -> 0.009406348
B5: 45992 | C5: =Sheet1!C208 -> 96158 | D5: =Sheet1!D208 -> 0.0086187753
B6: 46023 | C6: =Sheet1!C186 -> 97118 | D6: =Sheet1!D186 -> 0.0087261042
B7: 46054 | C7: =Sheet1!C164 -> 147622 | D7: =Sheet1!D164 -> 0.0081404345
B8: 46082 | C8: =Sheet1!C142 -> 221900 | D8: =Sheet1!D142 -> 0.0092903424
B9: 46113 | C9: =Sheet1!C120 -> 302413 | D9: =Sheet1!D120 -> 0.0095429377
B10: 46143 | C10: =Sheet1!C98 -> 436241 | D10: =Sheet1!D98 -> 0.011101381
B11: 46174 | C11: =Sheet1!C76 -> 509695 | D11: =Sheet1!D76 -> 0.011247011
B12: 46204 | C12: =Sheet1!C53 -> 565273 | D12: =Sheet1!D53 -> 0.011146896
B13: 46235 | C13: =Sheet1!C30 -> 561330 | D13: =Sheet1!D30 -> 0.01087672
B14: 46266 | C14: =Sheet1!C8 -> 507385 | D14: =Sheet1!D8 -> 0.010300962
C19: 45931 | D19: 45962 | E19: 45992 | F19: 46023 | G19: 46054 | H19: 46082 | I19: 46113 | J19: 46143 | K19: 46174 | L19: 46204 | M19: 46235 | N19: 46266
B20: members_classic_bike | C20: 143170 | D20: 88038 | E20: 37786 | F20: 37956 | G20: 55229 | H20: 72157 | I20: 99253 | J20: 129467 | K20: 144513 | L20: 149550 | M20: 147354 | N20: 130103
B21: members_e-bike | C21: 131177 | D21: 82729 | E21: 39537 | F21: 42601 | G21: 62755 | H21: 89254 | I21: 115750 | J21: 147941 | K21: 165629 | L21: 188391 | M21: 194146 | N21: 188922
B22: casula_clssic_bike | C22: 66161 | D22: 27060 | E22: 6950 | F22: 5821 | G22: 11529 | H22: 23656 | I22: 33720 | J22: 65898 | K22: 82578 | L22: 86256 | M22: 75535 | N22: 59165
B23: casual_e-bike | C23: 77369 | D23: 37183 | E23: 11885 | F23: 10740 | G23: 18109 | H23: 36833 | I23: 53690 | J23: 92935 | K23: 116975 | L23: 141076 | M23: 144295 | N23: 129195
C43: 45931 | D43: 45962 | E43: 45992 | F43: 46023 | G43: 46054 | H43: 46082 | I43: 46113 | J43: 46143 | K43: 46174 | L43: 46204 | M43: 46235 | N43: 46266
B44: classic bikes | C44: 209331 | D44: 115098 | E44: 44736 | F44: 43777 | G44: 66758 | H44: 95813 | I44: 132973 | J44: 195365 | K44: 227091 | L44: 235806 | M44: 222889 | N44: 189268
B45: e-bikes | C45: 208546 | D45: 119912 | E45: 51422 | F45: 53341 | G45: 80864 | H45: 126087 | I45: 169440 | J45: 240876 | K45: 282604 | L45: 329467 | M45: 338441 | N45: 318117
B46: members | C46: 274347 | D46: 170767 | E46: 77323 | F46: 80557 | G46: 117984 | H46: 161411 | I46: 215003 | J46: 277408 | K46: 310142 | L46: 337941 | M46: 341500 | N46: 319025
B47: casual | C47: 143530 | D47: 64243 | E47: 18835 | F47: 16561 | G47: 29638 | H47: 60489 | I47: 87410 | J47: 158833 | K47: 199553 | L47: 227332 | M47: 219830 | N47: 188360
C70: 45931 | D70: 45962 | E70: 45992 | F70: 46023 | G70: 46054 | H70: 46082 | I70: 46113 | J70: 46143 | K70: 46174 | L70: 46204 | M70: 46235 | N70: 46266
B71: start row | C71: 646039 | D71: 356628 | E71: 140534 | F71: 137787 | G71: 201449 | H71: 317038 | I71: 448252 | J71: 653704 | K71: 762551 | L71: 869051 | M71: 868191 | N71: 770562
B72: end row | C72: 417877 | D72: 235010 | E72: 96158 | F72: 97118 | G72: 147622 | H72: 221900 | I72: 302413 | J72: 436241 | K72: 509696 | L72: 565273 | M72: 561330 | N72: 507385
C73: 228162 | D73: 121618 | E73: 44376 | F73: 40669 | G73: 53827 | H73: 95138 | I73: 145839 | J73: 217463 | K73: 252855 | L73: 303778 | M73: 306861 | N73: 263177
B74: del % | C74: 35.317063 | D74: 34.102202 | E74: 31.5767 | F74: 29.515847 | G74: 26.719914 | H74: 30.00839 | I74: 32.535047 | J74: 33.26628 | K74: 33.159094 | L74: 34.955141 | M74: 35.344872 | N74: 34.153903 | O74: =AVERAGE(C74:N74) -> 32.554538

Sheet Sep-26
A1: Count of start_station_name | B1: Column Labels | C1: Column1 | D1: Column2 | E1: Column3 | F1: Column4 | G1: Column5 | H1: Column6 | I1: Column7
A2: Row Labels | B2: Sunday | C2: Monday | D2: Tuesday | E2: Wednesday | F2: Thursday | G2: Friday | H2: Saturday | I2: Grand Total
A3: 2112 W Peterson Ave | B3: 11 | C3: 19 | D3: 18 | E3: 10 | F3: 11 | G3: 11 | H3: 10 | I3: 90
A4: 21st St & Pulaski Rd | C4: 1 | D4: 2 | E4: 1 | F4: 2 | G4: 3 | I4: 9
A5: 63rd St Beach | B5: 108 | C5: 12 | D5: 26 | E5: 13 | F5: 23 | G5: 14 | H5: 26 | I5: 222
A6: 900 W Harrison St | B6: 50 | C6: 160 | D6: 251 | E6: 178 | F6: 154 | G6: 158 | H6: 90 | I6: 1041
A7: Aberdeen St & 103rd St | D7: 1 | I7: 1
A8: Aberdeen St & Carroll Ave | B8: 71 | C8: 115 | D8: 178 | E8: 165 | F8: 138 | G8: 115 | H8: 83 | I8: 865
A9: Aberdeen St & Jackson Blvd | B9: 120 | C9: 166 | D9: 228 | E9: 161 | F9: 155 | G9: 198 | H9: 166 | I9: 1194
A10: Aberdeen St & Monroe St | B10: 88 | C10: 89 | D10: 151 | E10: 122 | F10: 102 | G10: 122 | H10: 95 | I10: 769
A11: Aberdeen St & Randolph St | B11: 99 | C11: 102 | D11: 208 | E11: 167 | F11: 169 | G11: 155 | H11: 119 | I11: 1019
A12: Ada St & Washington Blvd | B12: 63 | C12: 65 | D12: 128 | E12: 104 | F12: 100 | G12: 123 | H12: 86 | I12: 669
A13: Addison/Racine Corral | B13: 17 | C13: 13 | D13: 16 | E13: 30 | F13: 30 | G13: 18 | H13: 23 | I13: 147
A14: Addison/Sheffield SE Corral | B14: 20 | C14: 17 | D14: 46 | E14: 35 | F14: 16 | G14: 11 | H14: 19 | I14: 164
A15: Addison/Sheffield SW Corral | B15: 11 | C15: 14 | D15: 44 | E15: 59 | F15: 29 | G15: 20 | H15: 17 | I15: 194
A16: Addison/Wilton Corral | B16: 4 | C16: 6 | D16: 23 | E16: 21 | F16: 20 | G16: 20 | H16: 14 | I16: 108
A17: Adler Planetarium | B17: 347 | C17: 269 | D17: 213 | E17: 165 | F17: 181 | G17: 242 | H17: 373 | I17: 1790
A18: Albany Ave & 16th St | B18: 6 | C18: 2 | D18: 2 | E18: 3 | F18: 2 | G18: 11 | H18: 7 | I18: 33
A19: Albany Ave & 26th St | C19: 2 | D19: 2 | E19: 1 | F19: 1 | G19: 4 | H19: 1 | I19: 11
A20: Albany Ave & Belmont Ave | B20: 12 | C20: 13 | D20: 20 | E20: 6 | F20: 11 | G20: 6 | H20: 14 | I20: 82
A21: Albany Ave & Bloomingdale Ave | B21: 61 | C21: 54 | D21: 63 | E21: 47 | F21: 63 | G21: 66 | H21: 72 | I21: 426
A22: Albany Ave & Douglas Blvd | C22: 1 | D22: 2 | E22: 3 | F22: 2 | G22: 11 | H22: 8 | I22: 27
A23: Albany Ave & Montrose Ave | B23: 26 | C23: 32 | D23: 34 | E23: 40 | F23: 36 | G23: 35 | H23: 30 | I23: 233
A24: Altgeld Gardens | B24: 1 | D24: 1 | I24: 2
A25: Archer (Damen) Ave & 37th St | B25: 2 | C25: 7 | D25: 10 | E25: 7 | F25: 6 | G25: 7 | H25: 8 | I25: 47
A26: Archer Ave & 43rd St | B26: 4 | C26: 3 | D26: 2 | E26: 1 | F26: 1 | G26: 1 | I26: 12
A27: Archer Ave & 49th St | C27: 1 | D27: 2 | E27: 3 | G27: 4 | H27: 1 | I27: 11
A28: Archer Ave & Homan Ave | B28: 4 | C28: 3 | D28: 4 | E28: 2 | F28: 1 | G28: 1 | H28: 4 | I28: 19
A29: Archer Ave & Wentworth Ave | B29: 49 | C29: 39 | D29: 54 | E29: 41 | F29: 46 | G29: 47 | H29: 62 | I29: 338
A30: Arrington Lagoon | B30: 16 | C30: 20 | D30: 13 | E30: 10 | F30: 20 | G30: 24 | H30: 29 | I30: 132
A31: Artesian Ave & 55th St | B31: 1 | C31: 5 | D31: 3 | E31: 2 | F31: 5 | G31: 5 | H31: 1 | I31: 22
A32: Artesian Ave & 71st St | C32: 2 | F32: 1 | G32: 3 | H32: 2 | I32: 8
A33: Artesian Ave & Hubbard St | B33: 33 | C33: 68 | D33: 137 | E33: 137 | F33: 112 | G33: 87 | H33: 39 | I33: 613
A34: Artesian Ave & Marquette Rd | D34: 1 | I34: 1
A35: Ashland Ave & 13th St | B35: 31 | C35: 70 | D35: 110 | E35: 88 | F35: 58 | G35: 97 | H35: 82 | I35: 536
A36: Ashland Ave & 50th St | C36: 1 | D36: 2 | F36: 2 | G36: 2 | H36: 2 | I36: 9
A37: Ashland Ave & 63rd St | D37: 2 | E37: 3 | H37: 4 | I37: 9
A38: Ashland Ave & 66th St | C38: 1 | D38: 2 | E38: 2 | F38: 2 | G38: 1 | H38: 1 | I38: 9
A39: Ashland Ave & 74th St | B39: 1 | C39: 1 | D39: 2 | F39: 3 | G39: 2 | H39: 1 | I39: 10
A40: Ashland Ave & Addison St | B40: 42 | C40: 35 | D40: 53 | E40: 40 | F40: 21 | G40: 38 | H40: 52 | I40: 281
...

Sheet Aug-26
A1: Count of start_station_name | B1: Column Labels | C1: Column1 | D1: Column2 | E1: Column3 | F1: Column4 | G1: Column5 | H1: Column6 | I1: Column7
A2: Row Labels | B2: Sunday | C2: Monday | D2: Tuesday | E2: Wednesday | F2: Thursday | G2: Friday | H2: Saturday | I2: Grand Total
A3: 2112 W Peterson Ave | B3: 21 | C3: 23 | D3: 8 | E3: 12 | F3: 15 | G3: 12 | H3: 20 | I3: 111
A4: 21st St & Pulaski Rd | B4: 2 | C4: 2 | D4: 2 | E4: 1 | F4: 1 | G4: 1 | H4: 2 | I4: 11
A5: 63rd St Beach | B5: 42 | C5: 15 | D5: 11 | E5: 9 | F5: 10 | G5: 22 | H5: 47 | I5: 156
A6: 900 W Harrison St | B6: 87 | C6: 151 | D6: 107 | E6: 129 | F6: 102 | G6: 134 | H6: 88 | I6: 798
A7: Aberdeen St & 103rd St | B7: 1 | E7: 2 | F7: 2 | I7: 5
A8: Aberdeen St & Carroll Ave | B8: 97 | C8: 162 | D8: 162 | E8: 161 | F8: 159 | G8: 105 | H8: 118 | I8: 964
A9: Aberdeen St & Jackson Blvd | B9: 182 | C9: 228 | D9: 175 | E9: 184 | F9: 151 | G9: 196 | H9: 203 | I9: 1319
A10: Aberdeen St & Monroe St | B10: 103 | C10: 152 | D10: 119 | E10: 106 | F10: 99 | G10: 114 | H10: 93 | I10: 786
A11: Aberdeen St & Randolph St | B11: 142 | C11: 150 | D11: 167 | E11: 171 | F11: 149 | G11: 122 | H11: 143 | I11: 1044
A12: Ada St & 113th Pl | E12: 2 | G12: 1 | I12: 3
A13: Ada St & Washington Blvd | B13: 77 | C13: 94 | D13: 89 | E13: 109 | F13: 105 | G13: 104 | H13: 63 | I13: 641
A14: Addison/Racine Corral | B14: 33 | C14: 36 | D14: 16 | E14: 11 | F14: 12 | G14: 17 | H14: 33 | I14: 158
A15: Addison/Sheffield SE Corral | B15: 6 | C15: 21 | D15: 13 | E15: 12 | F15: 7 | G15: 48 | H15: 16 | I15: 123
A16: Addison/Sheffield SW Corral | B16: 22 | C16: 60 | D16: 42 | E16: 18 | F16: 11 | G16: 69 | H16: 37 | I16: 259
A17: Addison/Wilton Corral | B17: 4 | C17: 13 | D17: 3 | E17: 13 | F17: 2 | G17: 16 | H17: 9 | I17: 60
A18: Adler Planetarium | B18: 341 | C18: 227 | D18: 253 | E18: 230 | F18: 225 | G18: 374 | H18: 340 | I18: 1990
A19: Albany Ave & 16th St | B19: 6 | C19: 4 | E19: 1 | F19: 3 | G19: 4 | H19: 2 | I19: 20
A20: Albany Ave & 26th St | B20: 4 | C20: 5 | E20: 2 | F20: 2 | G20: 2 | I20: 15
A21: Albany Ave & Belmont Ave | B21: 11 | C21: 19 | D21: 13 | E21: 15 | F21: 16 | G21: 22 | H21: 18 | I21: 114
A22: Albany Ave & Bloomingdale Ave | B22: 69 | C22: 68 | D22: 58 | E22: 51 | F22: 53 | G22: 62 | H22: 71 | I22: 432
A23: Albany Ave & Douglas Blvd | C23: 3 | D23: 1 | E23: 4 | F23: 2 | G23: 2 | I23: 12
A24: Albany Ave & Montrose Ave | B24: 42 | C24: 37 | D24: 41 | E24: 43 | F24: 35 | G24: 36 | H24: 46 | I24: 280
A25: Archer (Damen) Ave & 37th St | B25: 8 | C25: 5 | D25: 7 | E25: 9 | F25: 4 | G25: 2 | H25: 5 | I25: 40
A26: Archer Ave & 43rd St | C26: 1 | D26: 2 | E26: 1 | F26: 2 | G26: 3 | I26: 9
A27: Archer Ave & 49th St | B27: 2 | C27: 3 | F27: 2 | G27: 1 | I27: 8
A28: Archer Ave & Homan Ave | C28: 1 | D28: 2 | E28: 1 | F28: 3 | G28: 1 | H28: 1 | I28: 9
A29: Archer Ave & Wentworth Ave | B29: 43 | C29: 55 | D29: 30 | E29: 40 | F29: 27 | G29: 39 | H29: 72 | I29: 306
A30: Arrington Lagoon | B30: 30 | C30: 19 | D30: 18 | E30: 11 | F30: 6 | G30: 13 | H30: 18 | I30: 115
A31: Artesian Ave & 55th St | B31: 1 | C31: 2 | D31: 2 | E31: 3 | F31: 1 | G31: 2 | H31: 3 | I31: 14
A32: Artesian Ave & 71st St | B32: 1 | C32: 1 | D32: 1 | E32: 2 | F32: 1 | G32: 1 | H32: 1 | I32: 8
A33: Artesian Ave & Hubbard St | B33: 19 | C33: 104 | D33: 91 | E33: 114 | F33: 93 | G33: 49 | H33: 32 | I33: 502
A34: Artesian Ave & Marquette Rd | C34: 4 | I34: 4
A35: Ashland Ave & 13th St | B35: 70 | C35: 91 | D35: 75 | E35: 76 | F35: 36 | G35: 79 | H35: 54 | I35: 481
A36: Ashland Ave & 50th St | C36: 4 | D36: 3 | E36: 4 | F36: 1 | G36: 2 | H36: 3 | I36: 17
A37: Ashland Ave & 63rd St | D37: 1 | F37: 1 | G37: 2 | H37: 2 | I37: 6
A38: Ashland Ave & 66th St | D38: 2 | E38: 2 | F38: 1 | H38: 1 | I38: 6
A39: Ashland Ave & 74th St | B39: 3 | C39: 2 | D39: 1 | E39: 2 | F39: 1 | G39: 2 | H39: 3 | I39: 14
A40: Ashland Ave & 78th St | C40: 1 | E40: 1 | I40: 2
...

Sheet Jul-26
A1: Count of start_station_name | B1: Column Labels | C1: Column1 | D1: Column2 | E1: Column3 | F1: Column4 | G1: Column5 | H1: Column6 | I1: Column7
A2: Row Labels | B2: Sunday | C2: Monday | D2: Tuesday | E2: Wednesday | F2: Thursday | G2: Friday | H2: Saturday | I2: Grand Total
A3: 2112 W Peterson Ave | B3: 15 | C3: 15 | D3: 10 | E3: 19 | F3: 15 | G3: 20 | H3: 11 | I3: 105
A4: 21st St & Pulaski Rd | C4: 1 | D4: 1 | E4: 1 | F4: 4 | G4: 1 | H4: 1 | I4: 9
A5: 63rd St Beach | B5: 20 | C5: 25 | D5: 9 | E5: 19 | F5: 27 | G5: 18 | H5: 41 | I5: 159
A6: 900 W Harrison St | B6: 51 | C6: 76 | D6: 95 | E6: 139 | F6: 118 | G6: 115 | H6: 84 | I6: 678
A7: Aberdeen St & 103rd St | C7: 1 | D7: 1 | E7: 1 | H7: 1 | I7: 4
A8: Aberdeen St & Carroll Ave | B8: 102 | C8: 116 | D8: 148 | E8: 197 | F8: 182 | G8: 132 | H8: 96 | I8: 973
A9: Aberdeen St & Jackson Blvd | B9: 140 | C9: 162 | D9: 177 | E9: 241 | F9: 242 | G9: 240 | H9: 177 | I9: 1379
A10: Aberdeen St & Monroe St | B10: 98 | C10: 113 | D10: 133 | E10: 167 | F10: 159 | G10: 148 | H10: 105 | I10: 923
A11: Aberdeen St & Randolph St | B11: 106 | C11: 100 | D11: 124 | E11: 154 | F11: 158 | G11: 108 | H11: 88 | I11: 838
A12: Ada St & 113th Pl | D12: 1 | I12: 1
A13: Ada St & Washington Blvd | B13: 80 | C13: 71 | D13: 83 | E13: 158 | F13: 105 | G13: 109 | H13: 81 | I13: 687
A14: Addison/Racine Corral | B14: 24 | C14: 15 | D14: 22 | E14: 26 | F14: 8 | G14: 17 | H14: 30 | I14: 142
A15: Addison/Sheffield SE Corral | B15: 28 | C15: 8 | D15: 9 | E15: 14 | F15: 2 | G15: 16 | H15: 16 | I15: 93
A16: Addison/Sheffield SW Corral | B16: 40 | C16: 5 | D16: 32 | E16: 33 | F16: 7 | G16: 39 | H16: 61 | I16: 217
A17: Addison/Wilton Corral | B17: 14 | C17: 8 | D17: 24 | E17: 12 | G17: 18 | H17: 32 | I17: 108
A18: Adler Planetarium | B18: 406 | C18: 213 | D18: 273 | E18: 362 | F18: 231 | G18: 275 | H18: 400 | I18: 2160
A19: Albany Ave & 16th St | B19: 7 | C19: 2 | D19: 5 | E19: 3 | F19: 2 | G19: 1 | H19: 3 | I19: 23
A20: Albany Ave & 26th St | C20: 2 | D20: 1 | E20: 3 | F20: 2 | G20: 1 | H20: 2 | I20: 11
A21: Albany Ave & Belmont Ave | B21: 22 | C21: 19 | D21: 36 | E21: 21 | F21: 20 | G21: 28 | H21: 23 | I21: 169
A22: Albany Ave & Bloomingdale Ave | B22: 44 | C22: 39 | D22: 67 | E22: 62 | F22: 59 | G22: 72 | H22: 59 | I22: 402
A23: Albany Ave & Douglas Blvd | C23: 1 | E23: 2 | F23: 2 | I23: 5
A24: Albany Ave & Montrose Ave | B24: 30 | C24: 32 | D24: 39 | E24: 48 | F24: 50 | G24: 39 | H24: 39 | I24: 277
A25: Altgeld Gardens | B25: 1 | C25: 1 | D25: 1 | E25: 4 | F25: 4 | G25: 4 | H25: 1 | I25: 16
A26: Archer (Damen) Ave & 37th St | B26: 11 | C26: 5 | D26: 9 | E26: 10 | F26: 7 | G26: 3 | H26: 9 | I26: 54
A27: Archer Ave & 43rd St | C27: 1 | D27: 2 | E27: 1 | F27: 2 | I27: 6
A28: Archer Ave & 49th St | B28: 1 | C28: 1 | D28: 1 | F28: 3 | G28: 2 | H28: 2 | I28: 10
A29: Archer Ave & Homan Ave | B29: 1 | C29: 5 | D29: 1 | E29: 2 | F29: 2 | G29: 1 | H29: 2 | I29: 14
A30: Archer Ave & Wentworth Ave | B30: 86 | C30: 21 | D30: 42 | E30: 33 | F30: 64 | G30: 50 | H30: 93 | I30: 389
A31: Arrington Lagoon | F31: 1 | G31: 1 | I31: 2
A32: Artesian Ave & 55th St | B32: 4 | C32: 1 | D32: 2 | E32: 3 | F32: 4 | G32: 2 | H32: 3 | I32: 19
A33: Artesian Ave & 71st St | B33: 1 | E33: 1 | H33: 1 | I33: 3
A34: Artesian Ave & Hubbard St | B34: 32 | C34: 72 | D34: 94 | E34: 127 | F34: 100 | G34: 53 | H34: 32 | I34: 510
A35: Artesian Ave & Marquette Rd | D35: 1 | E35: 1 | F35: 1 | G35: 1 | H35: 1 | I35: 5
A36: Ashland Ave & 13th St | B36: 59 | C36: 48 | D36: 62 | E36: 41 | F36: 47 | G36: 54 | H36: 35 | I36: 346
A37: Ashland Ave & 50th St | C37: 2 | D37: 4 | E37: 5 | F37: 5 | G37: 2 | I37: 18
A38: Ashland Ave & 63rd St | E38: 1 | F38: 1 | G38: 1 | H38: 3 | I38: 6
A39: Ashland Ave & 66th St | C39: 1 | D39: 2 | I39: 3
A40: Ashland Ave & 74th St | E40: 3 | G40: 2 | I40: 5
...

Sheet Jun-26
A1: Count of start_station_name | B1: Column Labels | C1: Column1 | D1: Column2 | E1: Column3 | F1: Column4 | G1: Column5 | H1: Column6 | I1: Column7
A2: Row Labels | B2: Sunday | C2: Monday | D2: Tuesday | E2: Wednesday | F2: Thursday | G2: Friday | H2: Saturday | I2: Grand Total
A3: 2112 W Peterson Ave | B3: 7 | C3: 15 | D3: 8 | E3: 3 | F3: 8 | G3: 7 | H3: 13 | I3: 61
A4: 21st St & Pulaski Rd | C4: 1 | D4: 2 | E4: 1 | G4: 1 | H4: 4 | I4: 9
A5: 63rd St Beach | B5: 25 | C5: 22 | D5: 26 | E5: 8 | F5: 24 | G5: 31 | H5: 60 | I5: 196
A6: 900 W Harrison St | B6: 53 | C6: 91 | D6: 146 | E6: 107 | F6: 92 | G6: 94 | H6: 79 | I6: 662
A7: Aberdeen St & 103rd St | B7: 1 | C7: 1 | H7: 1 | I7: 3
A8: Aberdeen St & Carroll Ave | B8: 80 | C8: 157 | D8: 194 | E8: 143 | F8: 133 | G8: 122 | H8: 110 | I8: 939
A9: Aberdeen St & Jackson Blvd | B9: 132 | C9: 225 | D9: 224 | E9: 130 | F9: 173 | G9: 178 | H9: 174 | I9: 1236
A10: Aberdeen St & Monroe St | B10: 67 | C10: 112 | D10: 160 | E10: 97 | F10: 93 | G10: 100 | H10: 81 | I10: 710
A11: Aberdeen St & Randolph St | B11: 51 | C11: 83 | D11: 109 | E11: 105 | F11: 111 | G11: 85 | H11: 83 | I11: 627
A12: Ada St & 113th Pl | C12: 1 | D12: 4 | E12: 1 | F12: 2 | H12: 1 | I12: 9
A13: Ada St & Washington Blvd | B13: 45 | C13: 117 | D13: 114 | E13: 91 | F13: 110 | G13: 101 | H13: 86 | I13: 664
A14: Addison/Racine Corral | B14: 7 | C14: 26 | D14: 34 | E14: 18 | F14: 15 | G14: 33 | H14: 20 | I14: 153
A15: Addison/Sheffield SE Corral | B15: 8 | C15: 20 | D15: 25 | E15: 10 | F15: 12 | G15: 34 | H15: 17 | I15: 126
A16: Addison/Sheffield SW Corral | B16: 21 | C16: 35 | D16: 45 | E16: 14 | F16: 22 | G16: 59 | H16: 59 | I16: 255
A17: Addison/Wilton Corral | B17: 4 | C17: 12 | D17: 17 | E17: 7 | G17: 11 | H17: 26 | I17: 77
A18: Adler Planetarium | B18: 244 | C18: 224 | D18: 251 | E18: 123 | F18: 228 | G18: 263 | H18: 576 | I18: 1909
A19: Albany Ave & 16th St | B19: 4 | C19: 1 | D19: 2 | E19: 1 | F19: 3 | H19: 4 | I19: 15
A20: Albany Ave & 26th St | B20: 1 | C20: 4 | D20: 1 | E20: 2 | G20: 4 | H20: 4 | I20: 16
A21: Albany Ave & Belmont Ave | B21: 19 | C21: 27 | D21: 36 | E21: 19 | F21: 29 | G21: 25 | H21: 15 | I21: 170
A22: Albany Ave & Bloomingdale Ave | B22: 48 | C22: 52 | D22: 62 | E22: 45 | F22: 66 | G22: 56 | H22: 62 | I22: 391
A23: Albany Ave & Douglas Blvd | B23: 2 | C23: 4 | D23: 2 | E23: 1 | F23: 2 | G23: 3 | I23: 14
A24: Albany Ave & Montrose Ave | B24: 34 | C24: 28 | D24: 39 | E24: 33 | F24: 31 | G24: 46 | H24: 50 | I24: 261
A25: Altgeld Gardens | C25: 1 | D25: 1 | F25: 2 | H25: 2 | I25: 6
A26: Archer (Damen) Ave & 37th St | B26: 5 | C26: 11 | D26: 5 | E26: 6 | F26: 6 | G26: 8 | H26: 9 | I26: 50
A27: Archer Ave & 43rd St | B27: 1 | C27: 3 | D27: 2 | E27: 3 | G27: 1 | I27: 10
A28: Archer Ave & 49th St | B28: 1 | C28: 2 | D28: 2 | E28: 4 | F28: 1 | G28: 3 | H28: 1 | I28: 14
A29: Archer Ave & Homan Ave | B29: 1 | C29: 2 | D29: 1 | F29: 1 | G29: 4 | H29: 2 | I29: 11
A30: Archer Ave & Wentworth Ave | B30: 48 | C30: 37 | D30: 54 | E30: 26 | F30: 30 | G30: 54 | H30: 74 | I30: 323
A31: Artesian Ave & 55th St | B31: 1 | C31: 1 | D31: 1 | E31: 2 | F31: 1 | I31: 6
A32: Artesian Ave & 71st St | B32: 1 | G32: 2 | I32: 3
A33: Artesian Ave & Hubbard St | B33: 34 | C33: 97 | D33: 131 | E33: 90 | F33: 92 | G33: 60 | H33: 27 | I33: 531
A34: Artesian Ave & Marquette Rd | B34: 1 | C34: 1 | D34: 1 | E34: 1 | F34: 1 | I34: 5
A35: Ashland Ave & 13th St | B35: 31 | C35: 86 | D35: 91 | E35: 53 | F35: 55 | G35: 67 | H35: 59 | I35: 442
A36: Ashland Ave & 50th St | B36: 3 | C36: 6 | D36: 7 | E36: 6 | F36: 5 | G36: 5 | H36: 1 | I36: 33
A37: Ashland Ave & 63rd St | D37: 1 | F37: 1 | G37: 2 | H37: 1 | I37: 5
A38: Ashland Ave & 66th St | D38: 1 | F38: 1 | G38: 1 | I38: 3
A39: Ashland Ave & 74th St | B39: 2 | D39: 2 | E39: 5 | F39: 1 | G39: 4 | H39: 5 | I39: 19
A40: Ashland Ave & 78th St | C40: 1 | D40: 1 | G40: 1 | I40: 3
...

Sheet May-26
A1: Count of start_station_name | B1: Column Labels | C1: Column1 | D1: Column2 | E1: Column3 | F1: Column4 | G1: Column5 | H1: Column6 | I1: Column7
A2: Row Labels | B2: Sunday | C2: Monday | D2: Tuesday | E2: Wednesday | F2: Thursday | G2: Friday | H2: Saturday | I2: Grand Total
A3: 2112 W Peterson Ave | B3: 20 | C3: 14 | D3: 9 | E3: 9 | F3: 7 | G3: 16 | H3: 16 | I3: 91
A4: 21st St & Pulaski Rd | B4: 1 | C4: 1 | E4: 1 | G4: 3 | H4: 2 | I4: 8
A5: 63rd St Beach | B5: 29 | C5: 21 | D5: 13 | E5: 7 | F5: 8 | G5: 18 | H5: 18 | I5: 114
A6: 900 W Harrison St | B6: 57 | C6: 67 | D6: 66 | E6: 79 | F6: 58 | G6: 130 | H6: 71 | I6: 528
A7: Aberdeen St & 103rd St | B7: 1 | D7: 2 | E7: 3 | H7: 4 | I7: 10
A8: Aberdeen St & 106th St | D8: 1 | I8: 1
A9: Aberdeen St & Carroll Ave | B9: 61 | C9: 93 | D9: 104 | E9: 103 | F9: 113 | G9: 111 | H9: 88 | I9: 673
A10: Aberdeen St & Jackson Blvd | B10: 122 | C10: 151 | D10: 137 | E10: 165 | F10: 157 | G10: 179 | H10: 157 | I10: 1068
A11: Aberdeen St & Monroe St | B11: 94 | C11: 74 | D11: 90 | E11: 96 | F11: 107 | G11: 109 | H11: 96 | I11: 666
A12: Aberdeen St & Randolph St | B12: 104 | C12: 107 | D12: 108 | E12: 155 | F12: 146 | G12: 124 | H12: 137 | I12: 881
A13: Ada St & 113th Pl | D13: 1 | E13: 1 | G13: 2 | H13: 1 | I13: 5
A14: Ada St & Washington Blvd | B14: 68 | C14: 75 | D14: 83 | E14: 95 | F14: 94 | G14: 105 | H14: 71 | I14: 591
A15: Addison/Racine Corral | B15: 20 | C15: 21 | D15: 23 | E15: 34 | F15: 3 | G15: 13 | H15: 20 | I15: 134
A16: Addison/Sheffield SE Corral | B16: 14 | C16: 11 | D16: 19 | E16: 13 | F16: 2 | G16: 3 | H16: 14 | I16: 76
A17: Addison/Sheffield SW Corral | B17: 22 | C17: 47 | D17: 42 | E17: 9 | F17: 11 | G17: 17 | H17: 15 | I17: 163
A18: Addison/Wilton Corral | B18: 10 | C18: 17 | D18: 1 | E18: 2 | F18: 4 | G18: 9 | H18: 11 | I18: 54
A19: Adler Planetarium | B19: 304 | C19: 266 | D19: 153 | E19: 163 | F19: 131 | G19: 168 | H19: 417 | I19: 1602
A20: Albany Ave & 16th St | B20: 2 | C20: 1 | E20: 1 | F20: 3 | G20: 7 | H20: 2 | I20: 16
A21: Albany Ave & 26th St | E21: 3 | F21: 2 | G21: 5 | H21: 2 | I21: 12
A22: Albany Ave & Belmont Ave | B22: 23 | C22: 12 | D22: 18 | E22: 19 | F22: 21 | G22: 15 | H22: 23 | I22: 131
A23: Albany Ave & Bloomingdale Ave | B23: 55 | C23: 46 | D23: 49 | E23: 61 | F23: 44 | G23: 70 | H23: 62 | I23: 387
A24: Albany Ave & Douglas Blvd | B24: 1 | E24: 2 | F24: 2 | G24: 2 | H24: 3 | I24: 10
A25: Albany Ave & Montrose Ave | B25: 53 | C25: 29 | D25: 29 | E25: 33 | F25: 33 | G25: 47 | H25: 46 | I25: 270
A26: Altgeld Gardens | G26: 1 | I26: 1
A27: Archer (Damen) Ave & 37th St | B27: 10 | C27: 9 | D27: 6 | E27: 5 | F27: 4 | G27: 11 | H27: 11 | I27: 56
A28: Archer Ave & 43rd St | B28: 2 | C28: 1 | E28: 1 | F28: 3 | I28: 7
A29: Archer Ave & 49th St | C29: 1 | E29: 1 | H29: 2 | I29: 4
A30: Archer Ave & Homan Ave | B30: 1 | C30: 1 | D30: 1 | E30: 1 | F30: 1 | G30: 1 | I30: 6
A31: Archer Ave & Wentworth Ave | B31: 54 | C31: 31 | D31: 27 | E31: 19 | F31: 36 | G31: 34 | H31: 62 | I31: 263
A32: Artesian Ave & 55th St | C32: 3 | D32: 4 | E32: 4 | F32: 4 | G32: 3 | H32: 1 | I32: 19
A33: Artesian Ave & 71st St | B33: 4 | C33: 1 | I33: 5
A34: Artesian Ave & Hubbard St | B34: 37 | C34: 67 | D34: 78 | E34: 99 | F34: 106 | G34: 69 | H34: 24 | I34: 480
A35: Artesian Ave & Marquette Rd | B35: 1 | E35: 1 | F35: 2 | G35: 1 | H35: 4 | I35: 9
A36: Ashland Ave & 13th St | B36: 65 | C36: 46 | D36: 64 | E36: 55 | F36: 37 | G36: 58 | H36: 57 | I36: 382
A37: Ashland Ave & 50th St | C37: 4 | D37: 1 | E37: 4 | F37: 1 | G37: 5 | H37: 2 | I37: 17
A38: Ashland Ave & 63rd St | B38: 1 | C38: 1 | D38: 2 | E38: 1 | I38: 5
A39: Ashland Ave & 74th St | C39: 3 | D39: 2 | E39: 3 | F39: 2 | G39: 2 | H39: 1 | I39: 13
A40: Ashland Ave & 78th St | B40: 2 | D40: 1 | G40: 1 | I40: 4
...

Sheet Apr-26
A1: Count of start_station_name | B1: Column Labels | C1: Column1 | D1: Column2 | E1: Column3 | F1: Column4 | G1: Column5 | H1: Column6 | I1: Column7
A2: Row Labels | B2: Sunday | C2: Monday | D2: Tuesday | E2: Wednesday | F2: Thursday | G2: Friday | H2: Saturday | I2: Grand Total
A3: 2112 W Peterson Ave | B3: 4 | C3: 3 | D3: 9 | E3: 3 | F3: 11 | G3: 7 | H3: 6 | I3: 43
A4: 21st St & Pulaski Rd | C4: 1 | F4: 2 | G4: 2 | H4: 1 | I4: 6
A5: 63rd St Beach | B5: 24 | C5: 9 | D5: 14 | E5: 8 | F5: 23 | G5: 23 | H5: 22 | I5: 123
A6: 900 W Harrison St | B6: 37 | C6: 99 | D6: 147 | E6: 163 | F6: 152 | G6: 124 | H6: 60 | I6: 782
A7: Aberdeen St & 103rd St | F7: 2 | G7: 1 | I7: 3
A8: Aberdeen St & 106th St | F8: 1 | I8: 1
A9: Aberdeen St & Carroll Ave | B9: 41 | C9: 77 | D9: 113 | E9: 113 | F9: 117 | G9: 74 | H9: 48 | I9: 583
A10: Aberdeen St & Jackson Blvd | B10: 98 | C10: 127 | D10: 155 | E10: 159 | F10: 183 | G10: 149 | H10: 100 | I10: 971
A11: Aberdeen St & Monroe St | B11: 41 | C11: 64 | D11: 107 | E11: 100 | F11: 117 | G11: 79 | H11: 57 | I11: 565
A12: Aberdeen St & Randolph St | B12: 64 | C12: 88 | D12: 109 | E12: 123 | F12: 143 | G12: 95 | H12: 82 | I12: 704
A13: Ada St & 113th Place | C13: 1 | I13: 1
A14: Ada St & Washington Blvd | B14: 32 | C14: 56 | D14: 84 | E14: 116 | F14: 88 | G14: 60 | H14: 50 | I14: 486
A15: Addison/Racine Corral | B15: 15 | C15: 4 | D15: 17 | E15: 19 | F15: 19 | G15: 18 | H15: 14 | I15: 106
A16: Addison/Sheffield SE Corral | B16: 6 | C16: 1 | D16: 5 | E16: 8 | F16: 6 | G16: 9 | H16: 7 | I16: 42
A17: Addison/Sheffield SW Corral | B17: 13 | C17: 14 | D17: 18 | E17: 14 | F17: 12 | G17: 32 | H17: 22 | I17: 125
A18: Addison/Wilton Corral | B18: 9 | C18: 4 | D18: 6 | E18: 9 | F18: 1 | G18: 13 | H18: 6 | I18: 48
A19: Adler Planetarium | B19: 167 | C19: 55 | D19: 99 | E19: 115 | F19: 114 | G19: 103 | H19: 89 | I19: 742
A20: Albany Ave & 16th St | B20: 3 | C20: 3 | D20: 2 | E20: 3 | F20: 2 | G20: 1 | I20: 14
A21: Albany Ave & 26th St | B21: 3 | D21: 1 | E21: 2 | F21: 2 | G21: 3 | H21: 4 | I21: 15
A22: Albany Ave & Belmont Ave | B22: 6 | C22: 5 | D22: 4 | E22: 6 | F22: 10 | G22: 5 | H22: 2 | I22: 38
A23: Albany Ave & Bloomingdale Ave | B23: 35 | C23: 33 | D23: 40 | E23: 36 | F23: 47 | G23: 48 | H23: 26 | I23: 265
A24: Albany Ave & Douglas Blvd | B24: 2 | D24: 2 | F24: 2 | G24: 4 | H24: 2 | I24: 12
A25: Albany Ave & Montrose Ave | B25: 30 | C25: 18 | D25: 25 | E25: 33 | F25: 22 | G25: 17 | H25: 33 | I25: 178
A26: Archer (Damen) Ave & 37th St | B26: 3 | C26: 1 | E26: 7 | F26: 6 | G26: 9 | H26: 6 | I26: 32
A27: Archer Ave & 43rd St | B27: 1 | D27: 3 | F27: 4 | H27: 1 | I27: 9
A28: Archer Ave & 49th St | D28: 2 | E28: 3 | G28: 5 | I28: 10
A29: Archer Ave & Homan Ave | E29: 2 | F29: 1 | I29: 3
A30: Archer Ave & Wentworth Ave | B30: 27 | C30: 22 | D30: 21 | E30: 25 | F30: 26 | G30: 30 | H30: 28 | I30: 179
A31: Artesian Ave & 55th St | C31: 3 | D31: 3 | E31: 5 | F31: 5 | G31: 2 | H31: 1 | I31: 19
A32: Artesian Ave & 71st St | C32: 1 | E32: 1 | G32: 1 | H32: 1 | I32: 4
A33: Artesian Ave & Hubbard St | B33: 16 | C33: 56 | D33: 76 | E33: 94 | F33: 85 | G33: 45 | H33: 17 | I33: 389
A34: Artesian Ave & Marquette Rd | B34: 2 | C34: 1 | D34: 4 | E34: 1 | I34: 8
A35: Ashland Ave & 13th St | B35: 16 | C35: 33 | D35: 31 | E35: 40 | F35: 37 | G35: 39 | H35: 42 | I35: 238
A36: Ashland Ave & 50th St | B36: 2 | C36: 2 | D36: 3 | E36: 3 | F36: 3 | G36: 2 | I36: 15
A37: Ashland Ave & 66th St | D37: 1 | E37: 1 | I37: 2
A38: Ashland Ave & 74th St | E38: 1 | F38: 4 | G38: 1 | I38: 6
A39: Ashland Ave & 78th St | E39: 3 | I39: 3
A40: Ashland Ave & Augusta Blvd | B40: 47 | C40: 61 | D40: 88 | E40: 90 | F40: 96 | G40: 61 | H40: 46 | I40: 489
...

Sheet Mar-26
A1: Count of start_station_name | B1: Column Labels | C1: Column1 | D1: Column2 | E1: Column3 | F1: Column4 | G1: Column5 | H1: Column6 | I1: Column7
A2: Row Labels | B2: Sunday | C2: Monday | D2: Tuesday | E2: Wednesday | F2: Thursday | G2: Friday | H2: Saturday | I2: Grand Total
A3: Wilton Ave & Diversey Pkwy | B3: 8 | C3: 21 | D3: 33 | E3: 31 | F3: 27 | G3: 16 | H3: 16 | I3: 152
A4: 2112 W Peterson Ave | B4: 3 | C4: 3 | D4: 1 | E4: 4 | F4: 4 | G4: 6 | H4: 6 | I4: 27
A5: 21st St & Pulaski Rd | C5: 1 | D5: 1 | F5: 1 | G5: 1 | I5: 4
A6: 63rd St Beach | B6: 9 | C6: 13 | D6: 2 | E6: 6 | F6: 2 | G6: 6 | H6: 9 | I6: 47
A7: 900 W Harrison St | B7: 48 | C7: 97 | D7: 71 | E7: 76 | F7: 98 | G7: 59 | H7: 70 | I7: 519
A8: Aberdeen St & 103rd St | H8: 2 | I8: 2
A9: Aberdeen St & Carroll Ave | B9: 38 | C9: 90 | D9: 95 | E9: 62 | F9: 65 | G9: 56 | H9: 46 | I9: 452
A10: Aberdeen St & Jackson Blvd | B10: 106 | C10: 119 | D10: 135 | E10: 85 | F10: 109 | G10: 91 | H10: 87 | I10: 732
A11: Aberdeen St & Monroe St | B11: 49 | C11: 71 | D11: 86 | E11: 56 | F11: 60 | G11: 62 | H11: 55 | I11: 439
A12: Aberdeen St & Randolph St | B12: 59 | C12: 100 | D12: 117 | E12: 75 | F12: 94 | G12: 65 | H12: 60 | I12: 570
A13: Ada St & 113th Place | H13: 1 | I13: 1
A14: Ada St & Washington Blvd | B14: 43 | C14: 67 | D14: 62 | E14: 49 | F14: 58 | G14: 52 | H14: 34 | I14: 365
A15: Addison/Racine Corral | B15: 12 | C15: 13 | D15: 2 | E15: 5 | F15: 7 | G15: 5 | H15: 23 | I15: 67
A16: Addison/Sheffield SE Corral | B16: 10 | C16: 13 | F16: 1 | G16: 2 | H16: 8 | I16: 34
A17: Addison/Sheffield SW Corral | B17: 11 | C17: 29 | F17: 5 | G17: 2 | H17: 26 | I17: 73
A18: Addison/Wilton Corral | B18: 7 | C18: 10 | D18: 1 | G18: 2 | H18: 4 | I18: 24
A19: Adler Planetarium | B19: 124 | C19: 120 | D19: 37 | E19: 55 | F19: 36 | G19: 45 | H19: 181 | I19: 598
A20: Albany Ave & 16th St | C20: 1 | D20: 1 | F20: 1 | H20: 2 | I20: 5
A21: Albany Ave & 26th St | B21: 2 | C21: 4 | D21: 1 | F21: 1 | I21: 8
A22: Albany Ave & Belmont Ave | B22: 2 | C22: 5 | D22: 10 | E22: 5 | F22: 5 | G22: 2 | H22: 7 | I22: 36
A23: Albany Ave & Bloomingdale Ave | B23: 22 | C23: 35 | D23: 23 | E23: 20 | F23: 24 | G23: 17 | H23: 30 | I23: 171
A24: Albany Ave & Douglas Blvd | C24: 1 | F24: 1 | G24: 1 | H24: 1 | I24: 4
A25: Albany Ave & Montrose Ave | B25: 19 | C25: 18 | D25: 20 | E25: 12 | F25: 8 | G25: 15 | H25: 17 | I25: 109
A26: Archer (Damen) Ave & 37th St | B26: 3 | C26: 1 | D26: 1 | E26: 2 | F26: 6 | G26: 2 | H26: 1 | I26: 16
A27: Archer Ave & 43rd St | E27: 1 | G27: 3 | H27: 1 | I27: 5
A28: Archer Ave & 49th St | C28: 1 | D28: 4 | E28: 2 | F28: 1 | G28: 1 | H28: 1 | I28: 10
A29: Archer Ave & Homan Ave | B29: 2 | C29: 3 | E29: 1 | G29: 1 | I29: 7
A30: Archer Ave & Wentworth Ave | B30: 26 | C30: 26 | D30: 12 | E30: 19 | F30: 20 | G30: 13 | H30: 25 | I30: 141
A31: Artesian Ave & 55th St | B31: 1 | C31: 1 | E31: 1 | G31: 1 | I31: 4
A32: Artesian Ave & 71st St | B32: 2 | C32: 3 | E32: 1 | F32: 2 | G32: 1 | H32: 1 | I32: 10
A33: Artesian Ave & Hubbard St | B33: 22 | C33: 55 | D33: 67 | E33: 59 | F33: 55 | G33: 30 | H33: 15 | I33: 303
A34: Artesian Ave & Marquette Rd | C34: 2 | D34: 1 | I34: 3
A35: Ashland Ave & 13th St | B35: 35 | C35: 40 | D35: 25 | E35: 18 | F35: 17 | G35: 24 | H35: 19 | I35: 178
A36: Ashland Ave & 50th St | B36: 2 | C36: 2 | D36: 3 | E36: 2 | I36: 9
A37: Ashland Ave & 63rd St | C37: 3 | F37: 1 | G37: 2 | I37: 6
A38: Ashland Ave & 74th St | B38: 1 | D38: 2 | I38: 3
A39: Ashland Ave & 78th St | C39: 1 | I39: 1
A40: Ashland Ave & Archer Ave | B40: 7 | C40: 5 | D40: 3 | E40: 3 | F40: 9 | G40: 7 | H40: 3 | I40: 37
...

Sheet Feb-26
A1: Count of start_station_name | B1: Column Labels | C1: Column1 | D1: Column2 | E1: Column3 | F1: Column4 | G1: Column5 | H1: Column6 | I1: Column7
A2: Row Labels | B2: Sunday | C2: Monday | D2: Tuesday | E2: Wednesday | F2: Thursday | G2: Friday | H2: Saturday | I2: Grand Total
A3: 2112 W Peterson Ave | C3: 4 | D3: 1 | F3: 4 | G3: 3 | I3: 12
A4: 21st St & Pulaski Rd | D4: 2 | H4: 2 | I4: 4
A5: 63rd St Beach | B5: 5 | C5: 5 | E5: 3 | G5: 2 | H5: 1 | I5: 16
A6: 900 W Harrison St | B6: 28 | C6: 69 | D6: 90 | E6: 82 | F6: 73 | G6: 82 | H6: 36 | I6: 460
A7: Aberdeen St & 103rd St | F7: 1 | I7: 1
A8: Aberdeen St & Carroll Ave | B8: 17 | C8: 40 | D8: 68 | E8: 54 | F8: 63 | G8: 57 | H8: 25 | I8: 324
A9: Aberdeen St & Jackson Blvd | B9: 47 | C9: 63 | D9: 75 | E9: 88 | F9: 89 | G9: 96 | H9: 63 | I9: 521
A10: Aberdeen St & Monroe St | B10: 26 | C10: 32 | D10: 55 | E10: 54 | F10: 60 | G10: 68 | H10: 28 | I10: 323
A11: Aberdeen St & Randolph St | B11: 27 | C11: 52 | D11: 69 | E11: 75 | F11: 64 | G11: 68 | H11: 32 | I11: 387
A12: Ada St & 113th Place | B12: 1 | I12: 1
A13: Ada St & Washington Blvd | B13: 11 | C13: 35 | D13: 41 | E13: 48 | F13: 55 | G13: 32 | H13: 21 | I13: 243
A14: Addison/Racine Corral | B14: 3 | C14: 1 | D14: 2 | E14: 6 | F14: 2 | G14: 6 | H14: 4 | I14: 24
A15: Addison/Sheffield SE Corral | C15: 1 | G15: 1 | I15: 2
A16: Addison/Sheffield SW Corral | C16: 2 | I16: 2
A17: Addison/Wilton Corral | F17: 1 | H17: 1 | I17: 2
A18: Adler Planetarium | B18: 37 | C18: 30 | D18: 13 | E18: 38 | F18: 14 | G18: 59 | H18: 34 | I18: 225
A19: Albany Ave & 16th St | C19: 1 | G19: 1 | H19: 1 | I19: 3
A20: Albany Ave & 26th St | B20: 1 | F20: 1 | G20: 2 | I20: 4
A21: Albany Ave & Belmont Ave | B21: 4 | C21: 6 | D21: 3 | E21: 6 | F21: 11 | G21: 9 | H21: 1 | I21: 40
A22: Albany Ave & Bloomingdale Ave | B22: 12 | C22: 17 | D22: 20 | E22: 16 | F22: 17 | G22: 19 | H22: 14 | I22: 115
A23: Albany Ave & Douglas Blvd | C23: 2 | G23: 1 | I23: 3
A24: Albany Ave & Montrose Ave | B24: 9 | C24: 12 | D24: 13 | E24: 18 | F24: 15 | G24: 7 | H24: 15 | I24: 89
A25: Altgeld Gardens | B25: 1 | I25: 1
A26: Archer (Damen) Ave & 37th St | B26: 7 | C26: 3 | D26: 3 | G26: 3 | H26: 5 | I26: 21
A27: Archer Ave & 43rd St | F27: 1 | H27: 1 | I27: 2
A28: Archer Ave & 49th St | D28: 1 | I28: 1
A29: Archer Ave & Homan Ave | B29: 1 | E29: 2 | F29: 2 | G29: 1 | I29: 6
A30: Archer Ave & Wentworth Ave | B30: 3 | C30: 14 | D30: 3 | E30: 14 | F30: 11 | G30: 16 | H30: 10 | I30: 71
A31: Artesian Ave & 55th St | C31: 2 | D31: 4 | E31: 3 | F31: 2 | G31: 1 | H31: 1 | I31: 13
A32: Artesian Ave & 71st St | B32: 1 | H32: 1 | I32: 2
A33: Artesian Ave & Hubbard St | B33: 6 | C33: 29 | D33: 36 | E33: 46 | F33: 41 | G33: 37 | H33: 16 | I33: 211
A34: Artesian Ave & Marquette Rd | B34: 1 | D34: 1 | E34: 4 | G34: 1 | I34: 7
A35: Ashland Ave & 13th St | B35: 12 | C35: 11 | D35: 20 | E35: 12 | F35: 24 | G35: 16 | H35: 17 | I35: 112
A36: Ashland Ave & 50th St | B36: 1 | C36: 2 | D36: 2 | E36: 4 | I36: 9
A37: Ashland Ave & 63rd St | C37: 1 | D37: 1 | E37: 1 | G37: 1 | I37: 4
A38: Ashland Ave & 78th St | D38: 1 | E38: 1 | F38: 1 | I38: 3
A39: Ashland Ave & Archer Ave | B39: 2 | C39: 6 | D39: 1 | E39: 1 | F39: 5 | G39: 10 | H39: 2 | I39: 27
A40: Ashland Ave & Augusta Blvd | B40: 22 | C40: 30 | D40: 46 | E40: 36 | F40: 47 | G40: 29 | H40: 14 | I40: 224
...

Sheet Jan-26
A1: Count of start_station_name | B1: Column Labels | C1: Column1 | D1: Column2 | E1: Column3 | F1: Column4 | G1: Column5 | H1: Column6 | I1: Column7
A2: Row Labels | B2: Sunday | C2: Monday | D2: Tuesday | E2: Wednesday | F2: Thursday | G2: Friday | H2: Saturday | I2: Grand Total
A3: 2112 W Peterson Ave | B3: 4 | C3: 2 | D3: 3 | F3: 1 | G3: 1 | H3: 2 | I3: 13
A4: 21st St & Pulaski Rd | D4: 1 | H4: 1 | I4: 2
A5: 63rd St Beach | F5: 1 | I5: 1
A6: 900 W Harrison St | B6: 13 | C6: 24 | D6: 36 | E6: 44 | F6: 30 | G6: 25 | H6: 12 | I6: 184
A7: Aberdeen St & Carroll Ave | B7: 12 | C7: 38 | D7: 60 | E7: 35 | F7: 49 | G7: 31 | H7: 19 | I7: 244
A8: Aberdeen St & Jackson Blvd | B8: 40 | C8: 56 | D8: 77 | E8: 65 | F8: 50 | G8: 54 | H8: 43 | I8: 385
A9: Aberdeen St & Monroe St | B9: 25 | C9: 23 | D9: 66 | E9: 51 | F9: 47 | G9: 45 | H9: 20 | I9: 277
A10: Aberdeen St & Randolph St | B10: 13 | C10: 42 | D10: 60 | E10: 51 | F10: 54 | G10: 30 | H10: 30 | I10: 280
A11: Ada St & Washington Blvd | B11: 8 | C11: 25 | D11: 37 | E11: 35 | F11: 32 | G11: 27 | H11: 12 | I11: 176
A12: Addison/Racine Corral | B12: 3 | C12: 1 | D12: 1 | E12: 1 | F12: 1 | G12: 1 | H12: 1 | I12: 9
A13: Addison/Sheffield SE Corral | C13: 1 | H13: 1 | I13: 2
A14: Addison/Sheffield SW Corral | B14: 1 | I14: 1
A15: Addison/Wilton Corral | B15: 1 | D15: 2 | E15: 1 | G15: 1 | H15: 2 | I15: 7
A16: Adler Planetarium | B16: 11 | C16: 10 | D16: 18 | E16: 29 | F16: 21 | G16: 21 | H16: 19 | I16: 129
A17: Albany Ave & 16th St | B17: 2 | D17: 1 | I17: 3
A18: Albany Ave & 26th St | C18: 1 | E18: 1 | H18: 1 | I18: 3
A19: Albany Ave & Belmont Ave | C19: 3 | D19: 1 | E19: 1 | F19: 2 | G19: 3 | H19: 2 | I19: 12
A20: Albany Ave & Bloomingdale Ave | B20: 9 | C20: 6 | D20: 8 | E20: 11 | F20: 8 | G20: 6 | H20: 7 | I20: 55
A21: Albany Ave & Montrose Ave | B21: 13 | C21: 6 | D21: 15 | E21: 10 | F21: 6 | G21: 5 | H21: 13 | I21: 68
A22: Archer (Damen) Ave & 37th St | C22: 1 | D22: 1 | G22: 4 | H22: 2 | I22: 8
A23: Archer Ave & 43rd St | F23: 1 | I23: 1
A24: Archer Ave & Homan Ave | F24: 1 | I24: 1
A25: Archer Ave & Wentworth Ave | B25: 6 | C25: 3 | D25: 6 | E25: 3 | F25: 2 | G25: 5 | H25: 7 | I25: 32
A26: Artesian Ave & 55th St | C26: 2 | D26: 2 | E26: 4 | F26: 2 | G26: 2 | I26: 12
A27: Artesian Ave & 71st St | D27: 2 | F27: 1 | G27: 1 | I27: 4
A28: Artesian Ave & Hubbard St | B28: 3 | C28: 23 | D28: 42 | E28: 46 | F28: 30 | G28: 17 | H28: 3 | I28: 164
A29: Artesian Ave & Marquette Rd | C29: 1 | E29: 1 | I29: 2
A30: Ashland Ave & 13th St | B30: 19 | C30: 5 | D30: 15 | E30: 7 | F30: 14 | G30: 11 | H30: 16 | I30: 87
A31: Ashland Ave & 50th St | B31: 1 | C31: 2 | D31: 3 | E31: 1 | F31: 3 | G31: 1 | I31: 11
A32: Ashland Ave & 66th St | D32: 1 | I32: 1
A33: Ashland Ave & 78th St | C33: 1 | I33: 1
A34: Ashland Ave & Archer Ave | B34: 1 | D34: 2 | E34: 1 | F34: 5 | G34: 5 | H34: 2 | I34: 16
A35: Ashland Ave & Augusta Blvd | B35: 9 | C35: 21 | D35: 50 | E35: 26 | F35: 27 | G35: 29 | H35: 22 | I35: 184
A36: Ashland Ave & Belle Plaine Ave | B36: 9 | C36: 5 | D36: 9 | E36: 12 | F36: 5 | G36: 12 | H36: 8 | I36: 60
A37: Ashland Ave & Blackhawk St | B37: 14 | C37: 21 | D37: 25 | E37: 18 | F37: 26 | G37: 12 | H37: 18 | I37: 134
A38: Ashland Ave & Chicago Ave | B38: 9 | C38: 23 | D38: 25 | E38: 35 | F38: 28 | G38: 31 | H38: 24 | I38: 175
A39: Ashland Ave & Garfield Blvd | D39: 1 | E39: 1 | I39: 2
A40: Ashland Ave & Grace St | B40: 5 | C40: 7 | D40: 14 | E40: 7 | F40: 3 | G40: 9 | H40: 12 | I40: 57
...

Sheet Nov-25
A1: Count of start_station_name | B1: Column Labels | C1: Column1 | D1: Column2 | E1: Column3 | F1: Column4 | G1: Column5 | H1: Column6 | I1: Column7
A2: Row Labels | B2: Sunday | C2: Monday | D2: Tuesday | E2: Wednesday | F2: Thursday | G2: Friday | H2: Saturday | I2: Grand Total
A3: 2112 W Peterson Ave | B3: 8 | C3: 4 | D3: 5 | E3: 10 | F3: 4 | G3: 4 | H3: 9 | I3: 44
A4: 21st St & Pulaski Rd | D4: 2 | H4: 1 | I4: 3
A5: 63rd St Beach | B5: 6 | C5: 1 | D5: 1 | E5: 3 | F5: 2 | G5: 6 | H5: 5 | I5: 24
A6: 900 W Harrison St | B6: 53 | C6: 104 | D6: 110 | E6: 118 | F6: 109 | G6: 123 | H6: 58 | I6: 675
A7: Aberdeen St & Carroll Ave | B7: 34 | C7: 86 | D7: 74 | E7: 97 | F7: 69 | G7: 76 | H7: 54 | I7: 490
A8: Aberdeen St & Jackson Blvd | B8: 90 | C8: 99 | D8: 135 | E8: 140 | F8: 121 | G8: 130 | H8: 114 | I8: 829
A9: Aberdeen St & Monroe St | B9: 53 | C9: 45 | D9: 60 | E9: 76 | F9: 79 | G9: 79 | H9: 51 | I9: 443
A10: Aberdeen St & Randolph St | B10: 53 | C10: 71 | D10: 117 | E10: 108 | F10: 100 | G10: 87 | H10: 86 | I10: 622
A11: Ada St & Washington Blvd | B11: 35 | C11: 60 | D11: 61 | E11: 58 | F11: 60 | G11: 57 | H11: 41 | I11: 372
A12: Addison/Racine Corral | B12: 6 | C12: 2 | D12: 5 | E12: 6 | F12: 2 | G12: 4 | H12: 10 | I12: 35
A13: Addison/Sheffield SE Corral | B13: 3 | G13: 1 | H13: 5 | I13: 9
A14: Addison/Sheffield SW Corral | G14: 1 | H14: 16 | I14: 17
A15: Addison/Wilton Corral | B15: 1 | D15: 1 | G15: 7 | H15: 8 | I15: 17
A16: Adler Planetarium | B16: 93 | C16: 33 | D16: 32 | E16: 59 | F16: 47 | G16: 93 | H16: 171 | I16: 528
A17: Albany Ave & 16th St | B17: 1 | C17: 1 | G17: 3 | H17: 5 | I17: 10
A18: Albany Ave & 26th St | B18: 3 | E18: 1 | F18: 4 | I18: 8
A19: Albany Ave & Belmont Ave | B19: 4 | C19: 6 | D19: 9 | E19: 3 | F19: 4 | G19: 5 | H19: 8 | I19: 39
A20: Albany Ave & Bloomingdale Ave | B20: 24 | C20: 23 | D20: 23 | E20: 34 | F20: 25 | G20: 35 | H20: 32 | I20: 196
A21: Albany Ave & Douglas Blvd | C21: 1 | D21: 1 | G21: 3 | H21: 3 | I21: 8
A22: Albany Ave & Montrose Ave | B22: 18 | C22: 11 | D22: 11 | E22: 13 | F22: 18 | G22: 20 | H22: 13 | I22: 104
A23: Archer (Damen) Ave & 37th St | B23: 1 | C23: 3 | D23: 3 | E23: 3 | F23: 5 | G23: 2 | H23: 2 | I23: 19
A24: Archer Ave & 43rd St | D24: 2 | G24: 1 | H24: 1 | I24: 4
A25: Archer Ave & 49th St | B25: 1 | D25: 1 | F25: 1 | G25: 1 | H25: 1 | I25: 5
A26: Archer Ave & Homan Ave | F26: 2 | G26: 3 | H26: 1 | I26: 6
A27: Archer Ave & Wentworth Ave | B27: 22 | C27: 13 | D27: 11 | E27: 7 | F27: 9 | G27: 16 | H27: 18 | I27: 96
A28: Artesian Ave & 55th St | B28: 1 | D28: 1 | F28: 1 | G28: 1 | I28: 4
A29: Artesian Ave & 71st St | D29: 1 | I29: 1
A30: Artesian Ave & Hubbard St | B30: 11 | C30: 60 | D30: 71 | E30: 69 | F30: 56 | G30: 38 | H30: 10 | I30: 315
A31: Ashland Ave & 13th St | B31: 36 | C31: 29 | D31: 27 | E31: 36 | F31: 19 | G31: 29 | H31: 46 | I31: 222
A32: Ashland Ave & 50th St | B32: 6 | C32: 3 | D32: 4 | E32: 3 | F32: 3 | G32: 4 | H32: 1 | I32: 24
A33: Ashland Ave & 63rd St | B33: 1 | C33: 1 | F33: 1 | H33: 1 | I33: 4
A34: Ashland Ave & 66th St | D34: 1 | F34: 1 | G34: 1 | H34: 1 | I34: 4
A35: Ashland Ave & 74th St | C35: 1 | F35: 1 | H35: 1 | I35: 3
A36: Ashland Ave & Archer Ave | B36: 6 | C36: 5 | D36: 10 | E36: 3 | F36: 7 | G36: 9 | H36: 10 | I36: 50
A37: Ashland Ave & Augusta Blvd | B37: 41 | C37: 74 | D37: 62 | E37: 64 | F37: 49 | G37: 70 | H37: 66 | I37: 426
A38: Ashland Ave & Belle Plaine Ave | B38: 15 | C38: 13 | D38: 20 | E38: 13 | F38: 14 | G38: 18 | H38: 24 | I38: 117
A39: Ashland Ave & Blackhawk St | B39: 37 | C39: 32 | D39: 44 | E39: 45 | F39: 45 | G39: 45 | H39: 57 | I39: 305
A40: Ashland Ave & Chicago Ave | B40: 32 | C40: 41 | D40: 56 | E40: 64 | F40: 57 | G40: 51 | H40: 73 | I40: 374
...

Sheet Dec-25
A1: Count of start_station_name | B1: Column Labels | C1: Column1 | D1: Column2 | E1: Column3 | F1: Column4 | G1: Column5 | H1: Column6 | I1: Column7
A2: Row Labels | B2: Sunday | C2: Monday | D2: Tuesday | E2: Wednesday | F2: Thursday | G2: Friday | H2: Saturday | I2: Grand Total
A3: 2112 W Peterson Ave | C3: 1 | E3: 1 | F3: 1 | G3: 3 | H3: 1 | I3: 7
A4: 63rd St Beach | D4: 1 | E4: 3 | G4: 2 | H4: 3 | I4: 9
A5: 900 W Harrison St | B5: 7 | C5: 28 | D5: 39 | E5: 30 | F5: 41 | G5: 25 | H5: 11 | I5: 181
A6: Aberdeen St & 103rd St | E6: 1 | I6: 1
A7: Aberdeen St & Carroll Ave | B7: 10 | C7: 33 | D7: 42 | E7: 41 | F7: 36 | G7: 36 | H7: 27 | I7: 225
A8: Aberdeen St & Jackson Blvd | B8: 18 | C8: 57 | D8: 81 | E8: 83 | F8: 53 | G8: 56 | H8: 54 | I8: 402
A9: Aberdeen St & Monroe St | B9: 10 | C9: 35 | D9: 45 | E9: 32 | F9: 24 | G9: 24 | H9: 18 | I9: 188
A10: Aberdeen St & Randolph St | B10: 13 | C10: 44 | D10: 57 | E10: 59 | F10: 39 | G10: 28 | H10: 22 | I10: 262
A11: Ada St & 113th Place | D11: 1 | I11: 1
A12: Ada St & Washington Blvd | B12: 11 | C12: 18 | D12: 31 | E12: 42 | F12: 29 | G12: 20 | H12: 19 | I12: 170
A13: Addison/Racine Corral | C13: 1 | D13: 2 | E13: 1 | F13: 3 | G13: 3 | H13: 1 | I13: 11
A14: Addison/Sheffield SE Corral | F14: 1 | I14: 1
A15: Addison/Sheffield SW Corral | F15: 1 | G15: 1 | I15: 2
A16: Addison/Wilton Corral | C16: 1 | E16: 1 | F16: 1 | I16: 3
A17: Adler Planetarium | B17: 11 | C17: 14 | D17: 33 | E17: 23 | F17: 21 | G17: 8 | H17: 26 | I17: 136
A18: Albany Ave & 16th St | C18: 1 | E18: 1 | I18: 2
A19: Albany Ave & 26th St | C19: 2 | D19: 1 | E19: 1 | I19: 4
A20: Albany Ave & Belmont Ave | D20: 1 | E20: 2 | F20: 1 | G20: 1 | H20: 6 | I20: 11
A21: Albany Ave & Bloomingdale Ave | B21: 5 | C21: 11 | D21: 11 | E21: 20 | F21: 4 | G21: 7 | H21: 12 | I21: 70
A22: Albany Ave & Douglas Blvd | G22: 2 | H22: 1 | I22: 3
A23: Albany Ave & Montrose Ave | B23: 7 | C23: 5 | D23: 8 | E23: 9 | F23: 9 | G23: 7 | H23: 7 | I23: 52
A24: Altgeld Gardens | G24: 1 | I24: 1
A25: Archer (Damen) Ave & 37th St | B25: 2 | C25: 2 | D25: 2 | E25: 1 | F25: 1 | H25: 2 | I25: 10
A26: Archer Ave & 49th St | E26: 1 | F26: 1 | G26: 1 | H26: 2 | I26: 5
A27: Archer Ave & Homan Ave | D27: 1 | F27: 2 | I27: 3
A28: Archer Ave & Wentworth Ave | B28: 4 | C28: 7 | D28: 10 | E28: 4 | F28: 4 | G28: 3 | H28: 9 | I28: 41
A29: Artesian Ave & 55th St | F29: 1 | I29: 1
A30: Artesian Ave & 71st St | D30: 1 | E30: 1 | H30: 1 | I30: 3
A31: Artesian Ave & Hubbard St | B31: 4 | C31: 20 | D31: 33 | E31: 31 | F31: 25 | G31: 20 | H31: 6 | I31: 139
A32: Artesian Ave & Marquette Rd | H32: 1 | I32: 1
A33: Ashland Ave & 13th St | B33: 11 | C33: 15 | D33: 28 | E33: 6 | F33: 16 | G33: 15 | H33: 16 | I33: 107
A34: Ashland Ave & 50th St | B34: 2 | C34: 1 | D34: 4 | E34: 2 | G34: 3 | H34: 3 | I34: 15
A35: Ashland Ave & 63rd St | E35: 1 | I35: 1
A36: Ashland Ave & 74th St | D36: 1 | H36: 1 | I36: 2
A37: Ashland Ave & 78th St | H37: 1 | I37: 1
A38: Ashland Ave & Archer Ave | B38: 2 | C38: 3 | D38: 2 | E38: 5 | F38: 3 | G38: 1 | H38: 1 | I38: 17
A39: Ashland Ave & Augusta Blvd | B39: 6 | C39: 21 | D39: 26 | E39: 25 | F39: 20 | G39: 15 | H39: 14 | I39: 127
A40: Ashland Ave & Belle Plaine Ave | B40: 2 | C40: 6 | D40: 8 | E40: 4 | F40: 6 | G40: 4 | H40: 5 | I40: 35
...

Sheet Oct-25
A1: Count of start_station_name | B1: Column Labels | C1: Column1 | D1: Column2 | E1: Column3 | F1: Column4 | G1: Column5 | H1: Column6 | I1: Column7
A2: Row Labels | B2: Sunday | C2: Monday | D2: Tuesday | E2: Wednesday | F2: Thursday | G2: Friday | H2: Saturday | I2: Grand Total
A3: 2112 W Peterson Ave | B3: 5 | C3: 13 | D3: 3 | E3: 12 | F3: 7 | G3: 17 | H3: 6 | I3: 63
A4: 21st St & Pulaski Rd | C4: 1 | G4: 2 | I4: 3
A5: 63rd St Beach | B5: 25 | C5: 12 | D5: 9 | E5: 4 | F5: 13 | G5: 7 | H5: 22 | I5: 92
A6: 900 W Harrison St | B6: 59 | C6: 180 | D6: 156 | E6: 200 | F6: 217 | G6: 180 | H6: 82 | I6: 1074
A7: Aberdeen St & 103rd St | C7: 2 | E7: 1 | I7: 3
A8: Aberdeen St & Carroll Ave | B8: 66 | C8: 127 | D8: 104 | E8: 156 | F8: 148 | G8: 136 | H8: 68 | I8: 805
A9: Aberdeen St & Jackson Blvd | B9: 132 | C9: 154 | D9: 177 | E9: 234 | F9: 224 | G9: 237 | H9: 179 | I9: 1337
A10: Aberdeen St & Monroe St | B10: 65 | C10: 81 | D10: 109 | E10: 121 | F10: 140 | G10: 138 | H10: 82 | I10: 736
A11: Aberdeen St & Randolph St | B11: 107 | C11: 149 | D11: 135 | E11: 167 | F11: 193 | G11: 138 | H11: 126 | I11: 1015
A12: Ada St & Washington Blvd | B12: 51 | C12: 79 | D12: 89 | E12: 123 | F12: 130 | G12: 109 | H12: 95 | I12: 676
A13: Addison/Racine Corral | B13: 8 | C13: 3 | D13: 7 | E13: 35 | F13: 40 | G13: 4 | H13: 15 | I13: 112
A14: Addison/Sheffield SE Corral | B14: 1 | C14: 2 | E14: 13 | F14: 1 | H14: 2 | I14: 19
A15: Addison/Sheffield SW Corral | B15: 1 | E15: 19 | F15: 13 | G15: 2 | H15: 4 | I15: 39
A16: Addison/Wilton Corral | B16: 5 | E16: 9 | F16: 21 | G16: 9 | H16: 5 | I16: 49
A17: Adler Planetarium | B17: 183 | C17: 111 | D17: 77 | E17: 163 | F17: 139 | G17: 227 | H17: 205 | I17: 1105
A18: Albany Ave & 16th St | E18: 2 | G18: 1 | I18: 3
A19: Albany Ave & 26th St | D19: 4 | E19: 1 | F19: 5 | G19: 3 | H19: 3 | I19: 16
A20: Albany Ave & Belmont Ave | B20: 14 | C20: 6 | D20: 2 | E20: 15 | F20: 12 | G20: 4 | H20: 10 | I20: 63
A21: Albany Ave & Bloomingdale Ave | B21: 38 | C21: 65 | D21: 45 | E21: 68 | F21: 75 | G21: 63 | H21: 55 | I21: 409
A22: Albany Ave & Douglas Blvd | B22: 3 | G22: 2 | H22: 1 | I22: 6
A23: Albany Ave & Montrose Ave | B23: 23 | C23: 15 | D23: 21 | E23: 25 | F23: 30 | G23: 17 | H23: 29 | I23: 160
A24: Altgeld Gardens | B24: 2 | D24: 1 | I24: 3
A25: Archer (Damen) Ave & 37th St | B25: 6 | C25: 5 | D25: 4 | E25: 3 | F25: 2 | G25: 5 | H25: 5 | I25: 30
A26: Archer Ave & 43rd St | E26: 2 | F26: 1 | G26: 1 | I26: 4
A27: Archer Ave & 49th St | D27: 1 | E27: 2 | G27: 1 | H27: 1 | I27: 5
A28: Archer Ave & Homan Ave | F28: 2 | G28: 1 | H28: 1 | I28: 4
A29: Archer Ave & Wentworth Ave | B29: 49 | C29: 16 | D29: 19 | E29: 21 | F29: 41 | G29: 42 | H29: 46 | I29: 234
A30: Artesian Ave & 55th St | C30: 1 | F30: 1 | G30: 1 | I30: 3
A31: Artesian Ave & 71st St | C31: 1 | G31: 1 | I31: 2
A32: Artesian Ave & Hubbard St | B32: 25 | C32: 71 | D32: 91 | E32: 115 | F32: 111 | G32: 59 | H32: 26 | I32: 498
A33: Artesian Ave & Marquette Rd | C33: 1 | F33: 1 | H33: 6 | I33: 8
A34: Ashland Ave & 13th St | B34: 42 | C34: 45 | D34: 38 | E34: 61 | F34: 46 | G34: 51 | H34: 57 | I34: 340
A35: Ashland Ave & 50th St | B35: 2 | C35: 1 | D35: 2 | E35: 3 | F35: 1 | G35: 1 | H35: 2 | I35: 12
A36: Ashland Ave & 63rd St | B36: 1 | G36: 2 | H36: 1 | I36: 4
A37: Ashland Ave & 66th St | D37: 2 | H37: 1 | I37: 3
A38: Ashland Ave & 74th St | B38: 1 | D38: 1 | I38: 2
A39: Ashland Ave & 78th St | C39: 2 | D39: 1 | I39: 3
A40: Ashland Ave & Archer Ave | B40: 8 | C40: 10 | D40: 7 | E40: 9 | F40: 8 | G40: 10 | H40: 6 | I40: 58
...

Sheet Sheet4
A3: Row Labels | B3: Sum of Sunday | C3: Sum of Monday | D3: Sum of Tuesday | E3: Sum of Wednesday | F3: Sum of Thursday | G3: Sum of Friday | H3: Sum of Saturday | I3: Sum of Grand Total
A4: 2112 W Peterson Ave | B4: 98 | C4: 116 | D4: 75 | E4: 83 | F4: 88 | G4: 107 | H4: 100 | I4: 667
A5: 21st St & Pulaski Rd | B5: 3 | C5: 9 | D5: 13 | E5: 5 | F5: 10 | G5: 14 | H5: 14 | I5: 68
A6: 63rd St Beach | B6: 293 | C6: 135 | D6: 112 | E6: 83 | F6: 133 | G6: 149 | H6: 254 | I6: 1159
A7: 900 W Harrison St | B7: 543 | C7: 1146 | D7: 1314 | E7: 1345 | F7: 1244 | G7: 1249 | H7: 741 | I7: 7582
A8: Aberdeen St & 103rd St | B8: 3 | C8: 4 | D8: 4 | E8: 8 | F8: 5 | G8: 1 | H8: 8 | I8: 33
A9: Aberdeen St & 106th St | D9: 1 | F9: 1 | I9: 2
A10: Aberdeen St & Carroll Ave | B10: 629 | C10: 1134 | D10: 1342 | E10: 1327 | F10: 1272 | G10: 1051 | H10: 782 | I10: 7537
A11: Aberdeen St & Jackson Blvd | B11: 1227 | C11: 1607 | D11: 1776 | E11: 1735 | F11: 1707 | G11: 1804 | H11: 1517 | I11: 11373
A12: Aberdeen St & Monroe St | B12: 719 | C12: 891 | D12: 1181 | E12: 1078 | F12: 1087 | G12: 1088 | H12: 781 | I12: 6825
A13: Aberdeen St & Randolph St | B13: 838 | C13: 1088 | D13: 1380 | E13: 1410 | F13: 1420 | G13: 1105 | H13: 1008 | I13: 8249
A14: Ada St & 113th Pl | C14: 1 | D14: 6 | E14: 4 | F14: 2 | G14: 3 | H14: 2 | I14: 18
A15: Ada St & 113th Place | B15: 1 | C15: 1 | D15: 1 | H15: 1 | I15: 4
A16: Ada St & Washington Blvd | B16: 524 | C16: 762 | D16: 902 | E16: 1028 | F16: 966 | G16: 899 | H16: 659 | I16: 5740
A17: Addison/Racine Corral | B17: 148 | C17: 136 | D17: 147 | E17: 192 | F17: 142 | G17: 139 | H17: 194 | I17: 1098
A18: Addison/Sheffield SE Corral | B18: 96 | C18: 95 | D18: 117 | E18: 105 | F18: 48 | G18: 125 | H18: 105 | I18: 691
A19: Addison/Sheffield SW Corral | B19: 142 | C19: 206 | D19: 223 | E19: 166 | F19: 111 | G19: 242 | H19: 257 | I19: 1347
A20: Addison/Wilton Corral | B20: 59 | C20: 71 | D20: 78 | E20: 75 | F20: 50 | G20: 106 | H20: 118 | I20: 557
A21: Adler Planetarium | B21: 2268 | C21: 1572 | D21: 1452 | E21: 1525 | F21: 1388 | G21: 1878 | H21: 2831 | I21: 12914
A22: Albany Ave & 16th St | B22: 31 | C22: 17 | D22: 13 | E22: 15 | F22: 16 | G22: 29 | H22: 26 | I22: 147
A23: Albany Ave & 26th St | B23: 14 | C23: 20 | D23: 11 | E23: 17 | F23: 20 | G23: 24 | H23: 17 | I23: 123
A24: Albany Ave & Belmont Ave | B24: 117 | C24: 121 | D24: 153 | E24: 118 | F24: 142 | G24: 125 | H24: 129 | I24: 905
A25: Albany Ave & Bloomingdale Ave | B25: 422 | C25: 449 | D25: 469 | E25: 471 | F25: 485 | G25: 521 | H25: 502 | I25: 3319
A26: Albany Ave & Douglas Blvd | B26: 8 | C26: 13 | D26: 8 | E26: 12 | F26: 13 | G26: 31 | H26: 19 | I26: 104
A27: Albany Ave & Montrose Ave | B27: 304 | C27: 243 | D27: 295 | E27: 317 | F27: 293 | G27: 291 | H27: 338 | I27: 2081
... A41: Ashland Ave & 63rd St | B41: 3 | C41: 6 | D41: 7 | E41: 7 | F41: 5 | G41: 10 | H41: 12 | I41: 50
A42: Ashland Ave & 66th St | C42: 2 | D42: 12 | E42: 5 | F42: 5 | G42: 3 | H42: 4 | I42: 31
A43: Ashland Ave & 74th St | B43: 8 | C43: 7 | D43: 11 | E43: 14 | F43: 12 | G43: 13 | H43: 12 | I43: 77
A44: Ashland Ave & 78th St | B44: 2 | C44: 6 | D44: 4 | E44: 6 | F44: 1 | G44: 3 | H44: 1 | I44: 23
A45: Ashland Ave & Addison St | B45: 50 | C45: 38 | D45: 53 | E45: 41 | F45: 24 | G45: 53 | H45: 62 | I45: 321
A46: Ashland Ave & Archer Ave | B46: 26 | C46: 29 | D46: 25 | E46: 22 | F46: 37 | G46: 42 | H46: 24 | I46: 205
A47: Ashland Ave & Augusta Blvd | B47: 631 | C47: 902 | D47: 1018 | E47: 941 | F47: 987 | G47: 888 | H47: 831 | I47: 6198
A48: Ashland Ave & Belle Plaine Ave | B48: 335 | C48: 294 | D48: 356 | E48: 327 | F48: 364 | G48: 387 | H48: 399 | I48: 2462
A49: Ashland Ave & Blackhawk St | B49: 803 | C49: 716 | D49: 715 | E49: 756 | F49: 799 | G49: 867 | H49: 1047 | I49: 5703
A50: Ashland Ave & Chicago Ave | B50: 594 | C50: 766 | D50: 882 | E50: 945 | F50: 871 | G50: 928 | H50: 917 | I50: 5903
A51: Ashland Ave & Division St | B51: 115 | C51: 99 | D51: 115 | E51: 185 | F51: 165 | G51: 114 | H51: 145 | I51: 938
A52: Ashland Ave & Garfield Blvd | B52: 9 | C52: 11 | D52: 17 | E52: 7 | F52: 11 | G52: 5 | H52: 12 | I52: 72
A53: Ashland Ave & Grace St | B53: 557 | C53: 489 | D53: 542 | E53: 522 | F53: 469 | G53: 623 | H53: 718 | I53: 3920
A54: Ashland Ave & Grand Ave | B54: 419 | C54: 478 | D54: 562 | E54: 696 | F54: 610 | G54: 623 | H54: 552 | I54: 3940
... A68: Avenue O & 134th St | B68: 4 | C68: 1 | D68: 1 | E68: 3 | F68: 2 | G68: 3 | H68: 6 | I68: 20
...

Sheet Sheet5
A1: Row Labels | B1: Sum of Grand Total
A2: Honore St & 71st St | B2: 1
A3: Kostner & 87th | B3: 1
A4: Public Rack - 61st St & Melvina Ave | B4: 1
A5: Public Rack - 63rd St & Meade Ave | B5: 1
A6: Public Rack - 63rd St and Natoma Ave | B6: 1
A7: Public Rack - 83rd Pl & Kedzie Ave N | B7: 1
A8: Public Rack - Ashland Ave & 63rd St | B8: 1
A9: Public Rack - Ashland Ave & 71st St | B9: 1
A10: Public Rack - Ashland Ave & 76th St | B10: 1
A11: Public Rack - Austin & 62nd | B11: 1
A12: Public Rack - Austin & Higgins | B12: 1
A13: Public Rack - Austin Ave & Archer Ave | B13: 1
... A1936: Navy Pier | B1936: 59770

Sheet Sheet2
A1: start location | B1: Sunday | C1: Monday | D1: Tuesday | E1: Wednesday | F1: Thursday | G1: Friday | H1: Saturday | I1: Grand Total | M1: Sunday | N1: Monday | O1: Tuesday | P1: Wednesday | Q1: Thursday | R1: Friday | S1: Saturday | T1: Grand Total
A2: 2112 W Peterson Ave | B2: 11 | C2: 19 | D2: 18 | E2: 10 | F2: 11 | G2: 11 | H2: 10 | I2: 90 | L2: 2112 W Peterson Ave | M2: =SUMIF($A$2:$A$16130,L2,$B$2:$B$16130) -> 98 | N2: =SUMIF($A$2:$A$16130,L2,$C$2:$C$16130) -> 116
A3: 2112 W Peterson Ave | B3: 21 | C3: 23 | D3: 8 | E3: 12 | F3: 15 | G3: 12 | H3: 20 | I3: 111 | L3: 21st St & Pulaski Rd | M3: =SUMIF($A$2:$A$16130,L3,$B$2:$B$16130) -> 3 | N3: =SUMIF($A$2:$A$16130,L3,$C$2:$C$16130) -> 9
A4: 2112 W Peterson Ave | B4: 15 | C4: 15 | D4: 10 | E4: 19 | F4: 15 | G4: 20 | H4: 11 | I4: 105 | L4: 63rd St Beach | M4: =SUMIF($A$2:$A$16130,L4,$B$2:$B$16130) -> 293 | N4: =SUMIF($A$2:$A$16130,L4,$C$2:$C$16130) -> 135
A5: 2112 W Peterson Ave | B5: 7 | C5: 15 | D5: 8 | E5: 3 | F5: 8 | G5: 7 | H5: 13 | I5: 61 | L5: 900 W Harrison St | M5: =SUMIF($A$2:$A$16130,L5,$B$2:$B$16130) -> 543 | N5: =SUMIF($A$2:$A$16130,L5,$C$2:$C$16130) -> 1146
A6: 2112 W Peterson Ave | B6: 20 | C6: 14 | D6: 9 | E6: 9 | F6: 7 | G6: 16 | H6: 16 | I6: 91 | L6: Aberdeen St & 103rd St | M6: =SUMIF($A$2:$A$16130,L6,$B$2:$B$16130) -> 3 | N6: =SUMIF($A$2:$A$16130,L6,$C$2:$C$16130) -> 4
A7: 2112 W Peterson Ave | B7: 4 | C7: 3 | D7: 9 | E7: 3 | F7: 11 | G7: 7 | H7: 6 | I7: 43 | L7: Aberdeen St & 106th St | M7: =SUMIF($A$2:$A$16130,L7,$B$2:$B$16130) -> 0 | N7: =SUMIF($A$2:$A$16130,L7,$C$2:$C$16130) -> 0
A8: 2112 W Peterson Ave | B8: 3 | C8: 3 | D8: 1 | E8: 4 | F8: 4 | G8: 6 | H8: 6 | I8: 27 | L8: Aberdeen St & Carroll Ave | M8: =SUMIF($A$2:$A$16130,L8,$B$2:$B$16130) -> 629 | N8: =SUMIF($A$2:$A$16130,L8,$C$2:$C$16130) -> 1134
A9: 2112 W Peterson Ave | C9: 4 | D9: 1 | F9: 4 | G9: 3 | I9: 12 | L9: Aberdeen St & Jackson Blvd | M9: =SUMIF($A$2:$A$16130,L9,$B$2:$B$16130) -> 1227 | N9: =SUMIF($A$2:$A$16130,L9,$C$2:$C$16130) -> 1607
A10: 2112 W Peterson Ave | B10: 4 | C10: 2 | D10: 3 | F10: 1 | G10: 1 | H10: 2 | I10: 13 | L10: Aberdeen St & Monroe St | M10: =SUMIF($A$2:$A$16130,L10,$B$2:$B$16130) -> 719 | N10: =SUMIF($A$2:$A$16130,L10,$C$2:$C$16130) -> 891
A11: 2112 W Peterson Ave | C11: 1 | E11: 1 | F11: 1 | G11: 3 | H11: 1 | I11: 7 | L11: Aberdeen St & Randolph St | M11: =SUMIF($A$2:$A$16130,L11,$B$2:$B$16130) -> 838 | N11: =SUMIF($A$2:$A$16130,L11,$C$2:$C$16130) -> 1088
A12: 2112 W Peterson Ave | B12: 8 | C12: 4 | D12: 5 | E12: 10 | F12: 4 | G12: 4 | H12: 9 | I12: 44 | L12: Ada St & 113th Pl | M12: =SUMIF($A$2:$A$16130,L12,$B$2:$B$16130) -> 0 | N12: =SUMIF($A$2:$A$16130,L12,$C$2:$C$16130) -> 1
A13: 2112 W Peterson Ave | B13: 5 | C13: 13 | D13: 3 | E13: 12 | F13: 7 | G13: 17 | H13: 6 | I13: 63 | L13: Ada St & 113th Place | M13: =SUMIF($A$2:$A$16130,L13,$B$2:$B$16130) -> 1 | N13: =SUMIF($A$2:$A$16130,L13,$C$2:$C$16130) -> 1
